Workbook

Sheet Ex.excel01
A1: Tabela de Produtos da Cafeteria
A2: ID_Produto | B2: Tipo_de_Cafe | C2: Tamanho | D2: Valor_Unitario | E2: Quantidade
A3: 2 | B3: Ara | C3: G | D3: 29.79 | E3: 20
A4: 1 | B4: Ara | C4: G | D4: 3.89 | E4: 10
A5: 3 | B5: Lib | C5: M | D5: 3.38 | E5: 30
A6: 4 | B6: Rob | C6: P | D6: 13.43 | E6: 40

Sheet Ex.excel02
A1: Falidos e Quebrados LTDA.
A2: FUNCIONARIO | B2: PRODUTO | C2: VENDAS | D2: RESULTADO
A3: Abrilina | B3: Mouse | C3: 8 | D3: {=_xlfn.IFS(Tabela2[[#This Row],[VENDAS]]>5,"Ótimo",Tabela2[[#This Row],[VENDAS]]<5,"Péssimo",Tabela2[[#This Row],[VENDAS]]=5,"Regular")} -> Ótimo
A4: Cheropita | B4: Teclado | C4: 5 | D4: {=_xlfn.IFS(Tabela2[[#This Row],[VENDAS]]>5,"Ótimo",Tabela2[[#This Row],[VENDAS]]<5,"Péssimo",Tabela2[[#This Row],[VENDAS]]=5,"Regular")} -> Regular
A5: Aldegunda | B5: Monitor | C5: 9 | D5: {=_xlfn.IFS(Tabela2[[#This Row],[VENDAS]]>5,"Ótimo",Tabela2[[#This Row],[VENDAS]]<5,"Péssimo",Tabela2[[#This Row],[VENDAS]]=5,"Regular")} -> Ótimo
A6: Arquibaldo | B6: Gabinete | C6: 4 | D6: {=_xlfn.IFS(Tabela2[[#This Row],[VENDAS]]>5,"Ótimo",Tabela2[[#This Row],[VENDAS]]<5,"Péssimo",Tabela2[[#This Row],[VENDAS]]=5,"Regular")} -> Péssimo
A7: Clarisbadeu | B7: Disquete | C7: 6 | D7: {=_xlfn.IFS(Tabela2[[#This Row],[VENDAS]]>5,"Ótimo",Tabela2[[#This Row],[VENDAS]]<5,"Péssimo",Tabela2[[#This Row],[VENDAS]]=5,"Regular")} -> Ótimo
A8: Fredolino | B8: Impressora | C8: 3 | D8: {=_xlfn.IFS(Tabela2[[#This Row],[VENDAS]]>5,"Ótimo",Tabela2[[#This Row],[VENDAS]]<5,"Péssimo",Tabela2[[#This Row],[VENDAS]]=5,"Regular")} -> Péssimo

Sheet Ex.excel03
A1: Notas Escolares
A2: RA | B2: Nome de Aluno | C2: Nota 1 Trimestre | D2: Nota 2 Trimestre | E2: Nota 3 Trimestre | F2: Média final | G2: Resultado
A3: 2001 | B3: Astro | C3: 5 | D3: 6 | E3: 8 | F3: =AVERAGE(Tabela3[[#This Row],[Nota 1 Trimestre]:[Nota 3 Trimestre]]) -> 6.3333333 | G3: =IF(Tabela3[[#This Row],[Média final]]>6,"Aprovado","Reprovado") -> Aprovado
A4: 2002 | B4: Celeste | C4: 10 | D4: 7 | E4: 8 | F4: =AVERAGE(Tabela3[[#This Row],[Nota 1 Trimestre]:[Nota 3 Trimestre]]) -> 8.3333333 | G4: =IF(Tabela3[[#This Row],[Média final]]>6,"Aprovado","Reprovado") -> Aprovado
A5: 2003 | B5: Elvira | C5: 5 | D5: 2 | E5: 8 | F5: =AVERAGE(Tabela3[[#This Row],[Nota 1 Trimestre]:[Nota 3 Trimestre]]) -> 5 | G5: =IF(Tabela3[[#This Row],[Média final]]>6,"Aprovado","Reprovado") -> Reprovado
A6: 2004 | B6: Homer | C6: 2 | D6: 1 | E6: 3 | F6: =AVERAGE(Tabela3[[#This Row],[Nota 1 Trimestre]:[Nota 3 Trimestre]]) -> 2 | G6: =IF(Tabela3[[#This Row],[Média final]]>6,"Aprovado","Reprovado") -> Reprovado
A7: 2005 | B7: Chevrolet da Silva | C7: 4 | D7: 7 | E7: 8 | F7: =AVERAGE(Tabela3[[#This Row],[Nota 1 Trimestre]:[Nota 3 Trimestre]]) -> 6.3333333 | G7: =IF(Tabela3[[#This Row],[Média final]]>6,"Aprovado","Reprovado") -> Aprovado

Sheet Ex.excel04
A1: Recrutamento para vaga de emprego
A2: Nome | B2: Idade | C2: Ensino Médio | D2: Curso técnico | E2: Anos de experiência na área | F2: Situação
A3: Alfa Romeu Julia | B3: 17 | C3: Não | D3: Sim | E3: 1 | F3: =IF(AND(Tabela4[[#This Row],[Idade]]>=18,Tabela4[[#This Row],[Ensino Médio]]="Sim",Tabela4[[#This Row],[Curso técnico ]]="Sim",Tabela4[[#This Row],[Anos de experiência na área]]>=3)=TRUE,"Apto","Não Apto") -> Não Apto
A4: Fusclaudia de Oliveira | B4: 24 | C4: Sim | D4: Sim | E4: 3 | F4: =IF(AND(Tabela4[[#This Row],[Idade]]>=18,Tabela4[[#This Row],[Ensino Médio]]="Sim",Tabela4[[#This Row],[Curso técnico ]]="Sim",Tabela4[[#This Row],[Anos de experiência na área]]>=3)=TRUE,"Apto","Não Apto") -> Apto
A5: Unotavio do Santos | B5: 28 | C5: Sim | D5: Sim | E5: 4 | F5: =IF(AND(Tabela4[[#This Row],[Idade]]>=18,Tabela4[[#This Row],[Ensino Médio]]="Sim",Tabela4[[#This Row],[Curso técnico ]]="Sim",Tabela4[[#This Row],[Anos de experiência na área]]>=3)=TRUE,"Apto","Não Apto") -> Apto
A6: Nissan Silvia | B6: 18 | C6: Sim | D6: Não | E6: 1 | F6: =IF(AND(Tabela4[[#This Row],[Idade]]>=18,Tabela4[[#This Row],[Ensino Médio]]="Sim",Tabela4[[#This Row],[Curso técnico ]]="Sim",Tabela4[[#This Row],[Anos de experiência na área]]>=3)=TRUE,"Apto","Não Apto") -> Não Apto
A7: Ferrari Enzo | B7: 22 | C7: Sim | D7: Sim | E7: 2 | F7: =IF(AND(Tabela4[[#This Row],[Idade]]>=18,Tabela4[[#This Row],[Ensino Médio]]="Sim",Tabela4[[#This Row],[Curso técnico ]]="Sim",Tabela4[[#This Row],[Anos de experiência na área]]>=3)=TRUE,"Apto","Não Apto") -> Não Apto
A9: Requisitos para ser contratado
A10: Ter idade maior ou igual a 18 anos
A11: Ter ensino médio completo
A12: Ter curso de vendedor
A13: Ter no mínimo 3 anos de experiência na área

Sheet Base_Dirty (2)
A1: status | B1: nome | C1: cpf | D1: cpfclean | E1: idade | F1: data_nascimento | G1: cidade | H1: regiao | I1: renda_mensal | J1: credito_tomado | K1: flag_inadimplente | L1: qtde_batalhas | M1: nivel_risco | N1: flag_inadimplente2 | O1: valor_solicitado
A2: Ativo | B2: Ellaria Baelish | C2: 000.000.336-00 | D2: =TEXT(TabelaDirty[[#This Row],[cpf]],"000\.000\.000\-00") -> 000.000.336-00 | E2: 32 | F2: 34347 | G2: Ninho da Águia | H2: Vale | I2: 15600 | J2: 0 | K2: Sim | L2: 34 | N2: Sim | O2: 16000
A3: Inativo | B3: Stannis Lannister | C3: 36100 | D3: =TEXT(TabelaDirty[[#This Row],[cpf]],"000\.000\.000\-00") -> 000.000.361-00 | E3: 24 | F3: 37313 | G3: Ponta Tempestade | H3: Terras da Tempestade | I3: 11000 moedas | J3: =PROCX(TabelaClean[@cpf];'Base_Dirty (2)'!D1:D7 | K3: Sim | L3: 33 | N3: Sim | O3: 26000
A4: Ativo | B4: Asha Hornwood | C4: 000.000.363-00 | D4: =TEXT(TabelaDirty[[#This Row],[cpf]],"000\.000\.000\-00") -> 000.000.363-00 | E4: 33 | F4: 34144 | G4: Pedra do Dragão | H4: Terras da Coroa | I4: 21500 moedas | J4: N/A | K4: não | L4: 22 | N4: não | O4: 51500
A5: Ativo | B5: Jorah Dondarrion | C5: 000.000.210-00 | D5: =TEXT(TabelaDirty[[#This Row],[cpf]],"000\.000\.000\-00") -> 000.000.210-00 | E5: 63 | F5: 23156 | G5: Pyke | Ilhas de Ferro | I5: 10400 moedas | J5: 8500 | K5: não | L5: 39 | N5: não | O5: 36500
A6: Ativo | B6: Jojen Florent | C6: 000.000.321-00 | D6: =TEXT(TabelaDirty[[#This Row],[cpf]],"000\.000\.000\-00") -> 000.000.321-00 | E6: 32 | F6: 34299 | G6: Ninho da Águia | H6: vale | I6: 30000 | K6: Não | L6: 5 | N6: Não | O6: 65000
A7: Ativo | B7: Olenna Baelish | C7: 000.000.191-00 | D7: =TEXT(TabelaDirty[[#This Row],[cpf]],"000\.000\.000\-00") -> 000.000.191-00 | E7: 48 | F7: 28647 | G7: Lannisporto | I7: 13200 | J7: 3500 moedas | K7: Não | L7: 1 | N7: Não | O7: 32500
A8: ATIVO | B8: Brienne Manderly | C8: 000.000.076-00 | D8: =TEXT(TabelaDirty[[#This Row],[cpf]],"000\.000\.000\-00") -> 000.000.076-00 | E8: 28 | F8: 35830 | G8: Lannisporto | H8: Oeste | I8: 8600 moedas | J8: 19000 | K8: Sim | L8: 4 | N8: Sim | O8: 32500
A9: Inativo | B9: yara targaryen | C9: 000.000.059-00 | D9: =TEXT(TabelaDirty[[#This Row],[cpf]],"000\.000\.000\-00") -> 000.000.059-00 | E9: 42 | F9: 30810 | G9: Pyke | H9: Ilhas De Ferro | I9: 18200 moedas | J9: 31000 moedas | K9: Não | L9: 19 | N9: Não | O9: 63500
A10: Ativo | B10: Margaery Tarly | C10: 000.000.274-00 | D10: =TEXT(TabelaDirty[[#This Row],[cpf]],"000\.000\.000\-00") -> 000.000.274-00 | E10: 34 | F10: 33624 | G10: Pyke | H10: ilhas de ferro | I10: 8000 | J10: 14500 | K10: Sim | L10: 9 | N10: Sim | O10: 17500
A11: Inativo | B11: Viserys Seaworth | C11: 000.000.024-00 | D11: =TEXT(TabelaDirty[[#This Row],[cpf]],"000\.000\.000\-00") -> 000.000.024-00 | E11: 61 | F11: 23667 | G11: Meereen | H11: Essos | I11: 23000 moedas | J11: 44500 | K11: Sim | L11: 32 | N11: Sim | O11: 2000
A12: Ativo | B12: Tormund Cerwyn | C12: 000.000.039-00 | D12: =TEXT(TabelaDirty[[#This Row],[cpf]],"000\.000\.000\-00") -> 000.000.039-00 | E12: 33 | F12: 34147 | G12: Meereen | H12: Essos | I12: 28700 | J12: 12500 | K12: Não | L12: 41 | N12: Não | O12: 99500
A13: Ativo | B13: catelyn westerling | C13: 35800 | D13: =TEXT(TabelaDirty[[#This Row],[cpf]],"000\.000\.000\-00") -> 000.000.358-00 | E13: 70 | F13: 20515 | G13: Braavos | H13: Essos | I13: 19500 moedas | J13: 62000 | K13: Sim | L13: 45 | N13: Sim | O13: 35500
A14: Ativo | B14: Robb Baratheon | C14: 000.000.365-00 | D14: =TEXT(TabelaDirty[[#This Row],[cpf]],"000\.000\.000\-00") -> 000.000.365-00 | E14: 54 | F14: 26382 | G14: Ponta Tempestade | H14: Terras da Tempestade | I14: 22100 | J14: 37000 | K14: Não | L14: 34 | N14: Não | O14: 87000
A15: Ativo | B15: Asha Tallhart | C15: 8600 | D15: =TEXT(TabelaDirty[[#This Row],[cpf]],"000\.000\.000\-00") -> 000.000.086-00 | F15: 32260 | G15: Pyke | H15: Ilhas de Ferro | I15: 17600 moedas | J15: 0 | K15: Sim | L15: 31 | N15: Sim | O15: 47500
A16: Inativo | B16: Missandei Tarly | C16: 200 | D16: =TEXT(TabelaDirty[[#This Row],[cpf]],"000\.000\.000\-00") -> 000.000.002-00 | E16: 55 | F16: 25892 | G16: Ponta Tempestade | H16: TERRAS DA TEMPESTADE | I16: 5300 | J16: 6500 | K16: Não | L16: 42 | N16: Não | O16: 96000
A17: Inativo | B17: Jeor Mallister | C17: 000.000.162-00 | D17: =TEXT(TabelaDirty[[#This Row],[cpf]],"000\.000\.000\-00") -> 000.000.162-00 | E17: 47 | F17: 29064 | G17: Correrrio | H17: Terras Fluviais | I17: 13300 | J17: 1000 | K17: Sim | L17: 24 | N17: Sim | O17: 61500
A18: Inativo | B18: Eddard Crakehall | C18: 31800 | D18: =TEXT(TabelaDirty[[#This Row],[cpf]],"000\.000\.000\-00") -> 000.000.318-00 | E18: 43 | F18: 30391 | G18: Castelo Negro | H18: Norte | I18: 7100 | J18: 5500 moedas | K18: Não | L18: 23 | N18: Não | O18: 67000
A19: Ativo | B19: Podrick Swyft | C19: 000.000.090-00 | D19: =TEXT(TabelaDirty[[#This Row],[cpf]],"000\.000\.000\-00") -> 000.000.090-00 | E19: 32 | F19: 34457 | G19: Correrrio | H19: TERRAS FLUVIAIS | I19: 21300 | J19: 48000 | K19: Não | L19: 11 | N19: Não | O19: 35000
A20: Ativo | B20: Podrick Dayne | C20: 22300 | D20: =TEXT(TabelaDirty[[#This Row],[cpf]],"000\.000\.000\-00") -> 000.000.223-00 | E20: 25 | F20: 36831 | G20: Vilavelha | H20: Campina | I20: 9400 | J20: 51500 | K20: Não | L20: 14 | N20: Não | O20: 29500
A21: Ativo | B21: Ellaria Seaworth | C21: 000.000.125-00 | D21: =TEXT(TabelaDirty[[#This Row],[cpf]],"000\.000\.000\-00") -> 000.000.125-00 | E21: 23 | F21: 37627 | G21: Correrrio | H21: TERRAS FLUVIAIS | J21: 69000 | K21: Não | L21: 20 | N21: Não | O21: 69000
A22: Inativo | B22: Melisandre Clegane | C22: 000.000.231-00 | D22: =TEXT(TabelaDirty[[#This Row],[cpf]],"000\.000\.000\-00") -> 000.000.231-00 | E22: 53 | F22: 26629 | G22: Ilha dos Ursos | H22: NORTE | I22: 16500 | J22: 4000 | K22: Não | L22: 14 | N22: Não | O22: 36000
A23: Ativo | B23: Robert Karstark | C23: 000.000.184-00 | D23: =TEXT(TabelaDirty[[#This Row],[cpf]],"000\.000\.000\-00") -> 000.000.184-00 | F23: 21378 | G23: Meereen | I23: 14300 | J23: 32500 | K23: Sim | L23: 15 | N23: Sim | O23: 8000
A24: Inativo | B24: rhaegar stark | C24: 000.000.119-00 | D24: =TEXT(TabelaDirty[[#This Row],[cpf]],"000\.000\.000\-00") -> 000.000.119-00 | E24: 33 | F24: 34082 | G24: Meereen | H24: Essos | I24: 23600 | J24: 75500 | K24: Não | L24: 16 | N24: Não | O24: 88000
A25: Ativo | B25: Loras Greyjoy | C25: 000.000.362-00 | D25: =TEXT(TabelaDirty[[#This Row],[cpf]],"000\.000\.000\-00") -> 000.000.362-00 | E25: 68 | F25: 21145 | G25: Fosso Cailin | H25: Norte | I25: 29000 | J25: 67500 | K25: Não | L25: 25 | N25: Não | O25: 18000
A26: Inativo | B26: Jorah Hightower | C26: 000.000.346-00 | D26: =TEXT(TabelaDirty[[#This Row],[cpf]],"000\.000\.000\-00") -> 000.000.346-00 | E26: 62 | F26: 23259 | G26: Pedra do Dragão | H26: TERRAS DA COROA | J26: 0 | K26: Sim | L26: 1 batalhas | N26: Sim | O26: 12000
A27: Ativo | B27: Loras Clegane | C27: 000.000.287-00 | D27: =TEXT(TabelaDirty[[#This Row],[cpf]],"000\.000\.000\-00") -> 000.000.287-00 | E27: 58 | F27: 24911 | G27: Harrenhal | H27: Terras Fluviais | I27: 25400 | J27: 70500 | K27: Sim | L27: 11 | N27: Sim | O27: 47000
A28: Ativo | B28: samwell yronwood | C28: 000.000.124-00 | D28: =TEXT(TabelaDirty[[#This Row],[cpf]],"000\.000\.000\-00") -> 000.000.124-00 | E28: 29 | F28: 35323 | G28: Jardim de Cima | H28: Campina | I28: 21200 | J28: 75000 | K28: Não | L28: 6 | N28: Não | O28: 63500
A29: Ativoo | B29: Catelyn Yronwood | C29: 000.000.226-00 | D29: =TEXT(TabelaDirty[[#This Row],[cpf]],"000\.000\.000\-00") -> 000.000.226-00 | E29: 38 | F29: 32166 | G29: Castelo Negro | H29: norte | I29: 19500 moedas | J29: 39000 | K29: Não | L29: 25 | N29: Não | O29: 88500
A30: Inativo | B30: Brienne Reed | C30: 000.000.306-00 | D30: =TEXT(TabelaDirty[[#This Row],[cpf]],"000\.000\.000\-00") -> 000.000.306-00 | E30: 68 | F30: 21293 | G30: Pyke | H30: Ilhas de Ferro | I30: 3800 | J30: 70000 | K30: Sim | L30: 34 | N30: Sim | O30: 7500
A31: Ativo | B31: Rhaegar Umber | C31: 000.000.247-00 | D31: =TEXT(TabelaDirty[[#This Row],[cpf]],"000\.000\.000\-00") -> 000.000.247-00 | E31: 19 | F31: 39220 | G31: Vilavelha | H31: Campina | I31: 18000 | J31: 50500 | K31: sim | L31: 11 | N31: sim | O31: 26000
A32: Ativo | B32: Roose Manderly | C32: 15400 | D32: =TEXT(TabelaDirty[[#This Row],[cpf]],"000\.000\.000\-00") -> 000.000.154-00 | E32: 42 | F32: 30642 | G32: Dorne | H32: Dorne | I32: sem renda | J32: 19500 | K32: Não | L32: 42 | N32: Não | O32: 89500
A33: Ativo | B33: Jeor Florent | C33: 000.000.249-00 | D33: =TEXT(TabelaDirty[[#This Row],[cpf]],"000\.000\.000\-00") -> 000.000.249-00 | E33: 27 | F33: 36319 | G33: Ponta Tempestade | H33: terras da tempestade | I33: 28800 | J33: 78500 | K33: Não | L33: 2 | N33: Não | O33: 53000
A34: Ativo | B34: Bran Yronwood | C34: 000.000.057-00 | D34: =TEXT(TabelaDirty[[#This Row],[cpf]],"000\.000\.000\-00") -> 000.000.057-00 | E34: 42 | F34: 30878 | G34: Pyke | H34: Ilhas de Ferro | I34: 17500 | J34: 3500 | K34: Nao | L34: 25 | N34: Nao | O34: 35000
A35: Ativo | B35: BRONN ARRYN | C35: 000.000.016-00 | D35: =TEXT(TabelaDirty[[#This Row],[cpf]],"000\.000\.000\-00") -> 000.000.016-00 | E35: 44 | F35: 29975 | G35: Lannisporto | H35: oeste | I35: 5300 | J35: 6000 | K35: Sim | L35: 1 | N35: Sim | O35: 4500
A36: Ativo | B36: Shae Clegane | C36: 000.000.205-00 | D36: =TEXT(TabelaDirty[[#This Row],[cpf]],"000\.000\.000\-00") -> 000.000.205-00 | E36: 40 | F36: 31539 | G36: Fosso Cailin | H36: Norte | I36: 9900 | J36: 3500 | K36: Não | L36: 1 | N36: Não | O36: 23500
A37: Ativo | B37: Ramsay Hornwood | C37: 000.000.005-00 | D37: =TEXT(TabelaDirty[[#This Row],[cpf]],"000\.000\.000\-00") -> 000.000.005-00 | E37: 65 | F37: 22236 | G37: Pyke | H37: Ilhas De Ferro | I37: 23400 moedas | J37: 28000 | K37: Não | L37: 34 | N37: Não | O37: 74000
B38: MEERA PAYNE | C38: 000.000.131-00 | D38: =TEXT(TabelaDirty[[#This Row],[cpf]],"000\.000\.000\-00") -> 000.000.131-00 | E38: 63 | F38: 22974 | G38: Dorne | H38: DORNE | I38: 14700 | J38: 0 | K38: sim | L38: 40 | N38: sim | O38: 83500
A39: Ativo | B39: MELISANDRE BARATHEON | C39: 000.000.364-00 | D39: =TEXT(TabelaDirty[[#This Row],[cpf]],"000\.000\.000\-00") -> 000.000.364-00 | E39: 22 | G39: Meereen | H39: Essos | I39: 14400 | J39: 0 | K39: Não | L39: 27 batalhas | N39: Não | O39: 33500
A40: ATIVO | B40: Podrick Targaryen | C40: 000.000.050-00 | D40: =TEXT(TabelaDirty[[#This Row],[cpf]],"000\.000\.000\-00") -> 000.000.050-00 | E40: 39 | F40: 31879 | G40: Vilavelha | H40: Campina | I40: 29900 moedas | J40: 0 | K40: Não | L40: 39 | N40: Não | O40: 75000
...

Sheet Base_Limpa (2)
A1: status | B1: nome | C1: cpf | D1: idade | E1: data_nascimento | F1: cidade | G1: regiao | H1: CidadeCPF | I1: Coluna1 | J1: RegiaoCPF | K1: CidadeClean | L1: RegiaoClean | M1: renda_mensal | N1: credito_tomado | O1: flag_inadimplente | P1: analise_credito | Q1: qtde_batalhas | R1: nivel_risco | S1: analise_risco | T1: valor_solicitado | U1: liberacao_credito | Y1: regiao | AB1: Ativo | AE1: cpf | AJ1: renda_mensal | AN1: null | BB1: renda_mensal | BC1: liberacao_credito
A2: Inativo | B2: Varys Blackwood | C2: 000.000.267-00 | D2: 54 | E2: 26453 | F2: =TabelaClean14[[#This Row],[CidadeCPF]] -> Atalaia da Água Cinzenta | G2: =TabelaClean14[[#This Row],[RegiaoCPF]] -> Gargalo | H2: =_xlfn.XLOOKUP(TabelaClean14[[#This Row],[cpf]],TabelaDirty[cpfclean],TabelaDirty[cidade]) -> Atalaia da Água Cinzenta | I2: =_xlfn.XLOOKUP(TabelaClean14[[#This Row],[cpf]],TabelaDirty[cpfclean],TabelaDirty[regiao]) -> gargalo | J2: =PROPER(TabelaClean14[[#This Row],[Coluna1]]) -> Gargalo | K2: =_xlfn.TEXTBEFORE(TabelaClean14[[#This Row],[CidadeCPF]]," | ") -> #N/A | L2: =_xlfn.TEXTAFTER(TabelaClean14[[#This Row],[CidadeCPF]]," | ") -> #N/A | M2: 3900 | N2: 80000 | O2: Não | P2: =IF(AND(TabelaClean14[[#This Row],[credito_tomado]]>50000, TabelaClean14[[#This Row],[flag_inadimplente]]="Sim"), "Reprovado", IF(OR(ISBLANK(TabelaClean14[[#This Row],[credito_tomado]]), ISBLANK(TabelaClean14[[#This Row],[flag_inadimplente]])), "null", "Aprovado")) -> Aprovado | Q2: 41 | R2: {=_xlfn.IFS(TabelaClean14[[#This Row],[qtde_batalhas]]<=10,"Baixo",TabelaClean14[[#This Row],[qtde_batalhas]]>=26,"Alto",TabelaClean14[[#This Row],[qtde_batalhas]]<26,"Médio")} -> Alto | S2: =IF(AND(TabelaClean14[[#This Row],[nivel_risco]]="Alto",TabelaClean14[[#This Row],[flag_inadimplente]]="Sim"),"Arriscado","Ok") -> Ok | T2: 30000 | U2: =IF(AND(TabelaClean14[[#This Row],[analise_risco]]="Arriscado",TabelaClean14[[#This Row],[analise_credito]]="Reprovado"),0,IF(TabelaClean14[[#This Row],[status]]="Ativo",TabelaClean14[[#This Row],[valor_solicitado]]*1.08,0)) -> 0 | Y2: null | AB2: Inativo | AE2: 200 | AF2: =TEXT(AE2,"000\.000\.000\-00") -> 000.000.002-00 | AJ2: 28400 | AK2: 28400 | AM2: 78000 | AN2: 78000 | AO2: 78000 | AQ2: Lannisporto | AZ2: 000.000.161-00 | BA2: Lannisporto | BB2: 3900 | BC2: =IF(AND(TabelaClean14[[#This Row],[analise_risco]]="Arriscado",TabelaClean14[[#This Row],[analise_credito]]="Reprovado"),0,IF(TabelaClean14[[#This Row],[status]]="Ativo",TabelaClean14[[#This Row],[valor_solicitado]]*1.08,0)) -> 0
A3: Inativo | B3: Yara Payne | C3: 000.000.250-00 | D3: null | E3: 38001 | F3: =TabelaClean14[[#This Row],[CidadeCPF]] -> Fosso Cailin | G3: =TabelaClean14[[#This Row],[RegiaoCPF]] -> Norte | H3: =_xlfn.XLOOKUP(TabelaClean14[[#This Row],[cpf]],TabelaDirty[cpfclean],TabelaDirty[cidade]) -> Fosso Cailin | I3: =_xlfn.XLOOKUP(TabelaClean14[[#This Row],[cpf]],TabelaDirty[cpfclean],TabelaDirty[regiao]) -> NORTE | J3: =PROPER(TabelaClean14[[#This Row],[Coluna1]]) -> Norte | K3: =_xlfn.TEXTBEFORE(TabelaClean14[[#This Row],[CidadeCPF]]," | ") -> #N/A | L3: =_xlfn.TEXTAFTER(TabelaClean14[[#This Row],[CidadeCPF]]," | ") -> #N/A | M3: 2100 | N3: 79500 | O3: Sim | P3: =IF(AND(TabelaClean14[[#This Row],[credito_tomado]]>50000, TabelaClean14[[#This Row],[flag_inadimplente]]="Sim"), "Reprovado", IF(OR(ISBLANK(TabelaClean14[[#This Row],[credito_tomado]]), ISBLANK(TabelaClean14[[#This Row],[flag_inadimplente]])), "null", "Aprovado")) -> Reprovado | Q3: 29 | R3: {=_xlfn.IFS(TabelaClean14[[#This Row],[qtde_batalhas]]<=10,"Baixo",TabelaClean14[[#This Row],[qtde_batalhas]]>=26,"Alto",TabelaClean14[[#This Row],[qtde_batalhas]]<26,"Médio")} -> Alto | S3: =IF(AND(TabelaClean14[[#This Row],[nivel_risco]]="Alto",TabelaClean14[[#This Row],[flag_inadimplente]]="Sim"),"Arriscado","Ok") -> Arriscado | T3: 64000 | U3: =IF(AND(TabelaClean14[[#This Row],[analise_risco]]="Arriscado",TabelaClean14[[#This Row],[analise_credito]]="Reprovado"),0,IF(TabelaClean14[[#This Row],[status]]="Ativo",TabelaClean14[[#This Row],[valor_solicitado]]*1.08,0)) -> 0 | Y3: Campina | Z3: =PROPER(Y3) -> Campina | AE3: 2200 | AF3: =TEXT(AE3,"000\.000\.000\-00") -> 000.000.022-00 | AJ3: 23800 | AK3: 23800 | AM3: N/A | AN3: null | AO3: null | AQ3: Ninho da Águia | AZ3: 000.000.015-00 | BA3: Ninho da Águia | BB3: 2100 | BC3: =IF(AND(TabelaClean14[[#This Row],[analise_risco]]="Arriscado",TabelaClean14[[#This Row],[analise_credito]]="Reprovado"),0,IF(TabelaClean14[[#This Row],[status]]="Ativo",TabelaClean14[[#This Row],[valor_solicitado]]*1.08,0)) -> 0
A4: Ativo | B4: Beric Umber | C4: null | D4: 73 | E4: 19538 | F4: Null | G4: =TabelaClean14[[#This Row],[RegiaoCPF]] -> Null | H4: =_xlfn.XLOOKUP(TabelaClean14[[#This Row],[cpf]],TabelaDirty[cpfclean],TabelaDirty[cidade]) -> #N/A | I4: =_xlfn.XLOOKUP(TabelaClean14[[#This Row],[cpf]],TabelaDirty[cpfclean],TabelaDirty[regiao]) -> #N/A | J4: Null | K4: =_xlfn.TEXTBEFORE(TabelaClean14[[#This Row],[CidadeCPF]]," | ") -> #N/A | L4: =_xlfn.TEXTAFTER(TabelaClean14[[#This Row],[CidadeCPF]]," | ") -> #N/A | M4: 12700 | N4: 79500 | O4: null | P4: =IF(AND(TabelaClean14[[#This Row],[credito_tomado]]>50000, TabelaClean14[[#This Row],[flag_inadimplente]]="Sim"), "Reprovado", IF(OR(ISBLANK(TabelaClean14[[#This Row],[credito_tomado]]), ISBLANK(TabelaClean14[[#This Row],[flag_inadimplente]])), "null", "Aprovado")) -> Aprovado | Q4: 35 | R4: {=_xlfn.IFS(TabelaClean14[[#This Row],[qtde_batalhas]]<=10,"Baixo",TabelaClean14[[#This Row],[qtde_batalhas]]>=26,"Alto",TabelaClean14[[#This Row],[qtde_batalhas]]<26,"Médio")} -> Alto | S4: =IF(AND(TabelaClean14[[#This Row],[nivel_risco]]="Alto",TabelaClean14[[#This Row],[flag_inadimplente]]="Sim"),"Arriscado","Ok") -> Ok | T4: 39000 | U4: =IF(AND(TabelaClean14[[#This Row],[analise_risco]]="Arriscado",TabelaClean14[[#This Row],[analise_credito]]="Reprovado"),0,IF(TabelaClean14[[#This Row],[status]]="Ativo",TabelaClean14[[#This Row],[valor_solicitado]]*1.08,0)) -> 42120 | Y4: terras fluviais | Z4: =PROPER(Y4) -> Terras Fluviais | AE4: 2800 | AF4: =TEXT(AE4,"000\.000\.000\-00") -> 000.000.028-00 | AJ4: 8100 | AK4: 8100 | AM4: 27500 | AN4: 27500 | AO4: 27500 | AQ4: Jardim de Cima | AZ4: 000.000.182-00 | BA4: Jardim de Cima | BB4: 12700 | BC4: =IF(AND(TabelaClean14[[#This Row],[analise_risco]]="Arriscado",TabelaClean14[[#This Row],[analise_credito]]="Reprovado"),0,IF(TabelaClean14[[#This Row],[status]]="Ativo",TabelaClean14[[#This Row],[valor_solicitado]]*1.08,0)) -> 42120
A5: Inativo | B5: Aegon Umber | C5: 000.000.356-00 | D5: 66 | E5: 22101 | F5: =TabelaClean14[[#This Row],[CidadeCPF]] -> Meereen | G5: =TabelaClean14[[#This Row],[RegiaoCPF]] -> Essos | H5: =_xlfn.XLOOKUP(TabelaClean14[[#This Row],[cpf]],TabelaDirty[cpfclean],TabelaDirty[cidade]) -> Meereen | I5: =_xlfn.XLOOKUP(TabelaClean14[[#This Row],[cpf]],TabelaDirty[cpfclean],TabelaDirty[regiao]) -> ESSOS | J5: =PROPER(TabelaClean14[[#This Row],[Coluna1]]) -> Essos | K5: =_xlfn.TEXTBEFORE(TabelaClean14[[#This Row],[CidadeCPF]]," | ") -> #N/A | L5: =_xlfn.TEXTAFTER(TabelaClean14[[#This Row],[CidadeCPF]]," | ") -> #N/A | M5: 16800 | N5: 79500 | O5: Não | P5: =IF(AND(TabelaClean14[[#This Row],[credito_tomado]]>50000, TabelaClean14[[#This Row],[flag_inadimplente]]="Sim"), "Reprovado", IF(OR(ISBLANK(TabelaClean14[[#This Row],[credito_tomado]]), ISBLANK(TabelaClean14[[#This Row],[flag_inadimplente]])), "null", "Aprovado")) -> Aprovado | Q5: 36 | R5: {=_xlfn.IFS(TabelaClean14[[#This Row],[qtde_batalhas]]<=10,"Baixo",TabelaClean14[[#This Row],[qtde_batalhas]]>=26,"Alto",TabelaClean14[[#This Row],[qtde_batalhas]]<26,"Médio")} -> Alto | S5: =IF(AND(TabelaClean14[[#This Row],[nivel_risco]]="Alto",TabelaClean14[[#This Row],[flag_inadimplente]]="Sim"),"Arriscado","Ok") -> Ok | T5: 1500 | U5: =IF(AND(TabelaClean14[[#This Row],[analise_risco]]="Arriscado",TabelaClean14[[#This Row],[analise_credito]]="Reprovado"),0,IF(TabelaClean14[[#This Row],[status]]="Ativo",TabelaClean14[[#This Row],[valor_solicitado]]*1.08,0)) -> 0 | Y5: null | Z5: =PROPER(Y5) -> Null | AE5: 3200 | AF5: =TEXT(AE5,"000\.000\.000\-00") -> 000.000.032-00 | AJ5: 6800 | AK5: 6800 | AM5: 12000 | AN5: 12000 | AO5: 12000 | AQ5: Atalaia da Água Cinzenta | AZ5: 000.000.379-00 | BA5: Atalaia da Água Cinzenta | BB5: 16800 | BC5: =IF(AND(TabelaClean14[[#This Row],[analise_risco]]="Arriscado",TabelaClean14[[#This Row],[analise_credito]]="Reprovado"),0,IF(TabelaClean14[[#This Row],[status]]="Ativo",TabelaClean14[[#This Row],[valor_solicitado]]*1.08,0)) -> 0
A6: Ativo | B6: Meera Reed | C6: 000.000.314-00 | D6: 53 | E6: 26584 | F6: =TabelaClean14[[#This Row],[CidadeCPF]] -> Fosso Cailin | G6: =TabelaClean14[[#This Row],[RegiaoCPF]] -> Norte | H6: =_xlfn.XLOOKUP(TabelaClean14[[#This Row],[cpf]],TabelaDirty[cpfclean],TabelaDirty[cidade]) -> Fosso Cailin | I6: =_xlfn.XLOOKUP(TabelaClean14[[#This Row],[cpf]],TabelaDirty[cpfclean],TabelaDirty[regiao]) -> Norte | J6: =PROPER(TabelaClean14[[#This Row],[Coluna1]]) -> Norte | K6: =_xlfn.TEXTBEFORE(TabelaClean14[[#This Row],[CidadeCPF]]," | ") -> #N/A | L6: =_xlfn.TEXTAFTER(TabelaClean14[[#This Row],[CidadeCPF]]," | ") -> #N/A | M6: 12200 | N6: 79500 | O6: Não | P6: =IF(AND(TabelaClean14[[#This Row],[credito_tomado]]>50000, TabelaClean14[[#This Row],[flag_inadimplente]]="Sim"), "Reprovado", IF(OR(ISBLANK(TabelaClean14[[#This Row],[credito_tomado]]), ISBLANK(TabelaClean14[[#This Row],[flag_inadimplente]])), "null", "Aprovado")) -> Aprovado | Q6: 45 | R6: {=_xlfn.IFS(TabelaClean14[[#This Row],[qtde_batalhas]]<=10,"Baixo",TabelaClean14[[#This Row],[qtde_batalhas]]>=26,"Alto",TabelaClean14[[#This Row],[qtde_batalhas]]<26,"Médio")} -> Alto | S6: =IF(AND(TabelaClean14[[#This Row],[nivel_risco]]="Alto",TabelaClean14[[#This Row],[flag_inadimplente]]="Sim"),"Arriscado","Ok") -> Ok | T6: 57000 | U6: =IF(AND(TabelaClean14[[#This Row],[analise_risco]]="Arriscado",TabelaClean14[[#This Row],[analise_credito]]="Reprovado"),0,IF(TabelaClean14[[#This Row],[status]]="Ativo",TabelaClean14[[#This Row],[valor_solicitado]]*1.08,0)) -> 61560 | Y6: null | Z6: =PROPER(Y6) -> Null | AE6: 3400 | AF6: =TEXT(AE6,"000\.000\.000\-00") -> 000.000.034-00 | AJ6: 11100 moedas | AK6: 11100 | AM6: 63000 | AN6: 63000 | AO6: 63000 | AQ6: Ninho da Águia | AZ6: 000.000.180-00 | BA6: Ninho da Águia | BB6: 12200 | BC6: =IF(AND(TabelaClean14[[#This Row],[analise_risco]]="Arriscado",TabelaClean14[[#This Row],[analise_credito]]="Reprovado"),0,IF(TabelaClean14[[#This Row],[status]]="Ativo",TabelaClean14[[#This Row],[valor_solicitado]]*1.08,0)) -> 61560
A7: Ativo | B7: Roose Dondarrion | C7: 000.000.126-00 | D7: 53 | E7: 26620 | F7: =TabelaClean14[[#This Row],[CidadeCPF]] -> Ninho da Águia | G7: =TabelaClean14[[#This Row],[RegiaoCPF]] -> Vale | H7: =_xlfn.XLOOKUP(TabelaClean14[[#This Row],[cpf]],TabelaDirty[cpfclean],TabelaDirty[cidade]) -> Ninho da Águia | I7: =_xlfn.XLOOKUP(TabelaClean14[[#This Row],[cpf]],TabelaDirty[cpfclean],TabelaDirty[regiao]) -> vale | J7: =PROPER(TabelaClean14[[#This Row],[Coluna1]]) -> Vale | K7: =_xlfn.TEXTBEFORE(TabelaClean14[[#This Row],[CidadeCPF]]," | ") -> #N/A | L7: =_xlfn.TEXTAFTER(TabelaClean14[[#This Row],[CidadeCPF]]," | ") -> #N/A | M7: 21300 | N7: 79500 | O7: Não | P7: =IF(AND(TabelaClean14[[#This Row],[credito_tomado]]>50000, TabelaClean14[[#This Row],[flag_inadimplente]]="Sim"), "Reprovado", IF(OR(ISBLANK(TabelaClean14[[#This Row],[credito_tomado]]), ISBLANK(TabelaClean14[[#This Row],[flag_inadimplente]])), "null", "Aprovado")) -> Aprovado | Q7: 18 | R7: {=_xlfn.IFS(TabelaClean14[[#This Row],[qtde_batalhas]]<=10,"Baixo",TabelaClean14[[#This Row],[qtde_batalhas]]>=26,"Alto",TabelaClean14[[#This Row],[qtde_batalhas]]<26,"Médio")} -> Médio | S7: =IF(AND(TabelaClean14[[#This Row],[nivel_risco]]="Alto",TabelaClean14[[#This Row],[flag_inadimplente]]="Sim"),"Arriscado","Ok") -> Ok | T7: 19000 | U7: =IF(AND(TabelaClean14[[#This Row],[analise_risco]]="Arriscado",TabelaClean14[[#This Row],[analise_credito]]="Reprovado"),0,IF(TabelaClean14[[#This Row],[status]]="Ativo",TabelaClean14[[#This Row],[valor_solicitado]]*1.08,0)) -> 20520 | Y7: null | Z7: =PROPER(Y7) -> Null | AE7: 3800 | AF7: =TEXT(AE7,"000\.000\.000\-00") -> 000.000.038-00 | AJ7: 5100 | AK7: 5100 | AM7: 25000 | AN7: 25000 | AO7: 25000 | AQ7: Fosso Cailin | AZ7: 000.000.149-00 | BA7: Fosso Cailin | BB7: 21300 | BC7: =IF(AND(TabelaClean14[[#This Row],[analise_risco]]="Arriscado",TabelaClean14[[#This Row],[analise_credito]]="Reprovado"),0,IF(TabelaClean14[[#This Row],[status]]="Ativo",TabelaClean14[[#This Row],[valor_solicitado]]*1.08,0)) -> 20520
A8: Ativo | B8: Beric Umber | C8: 000.000.032-00 | D8: =_xlfn.XLOOKUP(TabelaClean14[[#This Row],[nome]],Base_Dirty!B:B,Base_Dirty!E:E) -> 73 | E8: =_xlfn.XLOOKUP(TabelaClean14[[#This Row],[nome]],Base_Dirty!$B:$B,Base_Dirty!F:F) -> 19538 | F8: Pedra do Dragão | G8: Terras Da Coroa | H8: terras da coroa | I8: 12700 | J8: 79500 | K8: Não | L8: 35 | M8: =_xlfn.XLOOKUP(TabelaClean14[[#This Row],[nome]],Base_Dirty!$B:$B,Base_Dirty!I:I) -> 12700 | N8: =_xlfn.XLOOKUP(TabelaClean14[[#This Row],[nome]],Base_Dirty!$B:$B,Base_Dirty!J:J) -> 79500 | O8: Não | P8: =IF(AND(TabelaClean14[[#This Row],[credito_tomado]]>50000, TabelaClean14[[#This Row],[flag_inadimplente]]="Sim"), "Reprovado", IF(OR(ISBLANK(TabelaClean14[[#This Row],[credito_tomado]]), ISBLANK(TabelaClean14[[#This Row],[flag_inadimplente]])), "null", "Aprovado")) -> Aprovado | Q8: =_xlfn.XLOOKUP(TabelaClean14[[#This Row],[nome]],Base_Dirty!$B:$B,Base_Dirty!L:L) -> 35 | R8: {=_xlfn.IFS(TabelaClean14[[#This Row],[qtde_batalhas]]<=10,"Baixo",TabelaClean14[[#This Row],[qtde_batalhas]]>=26,"Alto",TabelaClean14[[#This Row],[qtde_batalhas]]<26,"Médio")} -> Alto | S8: =IF(AND(TabelaClean14[[#This Row],[nivel_risco]]="Alto",TabelaClean14[[#This Row],[flag_inadimplente]]="Sim"),"Arriscado","Ok") -> Ok | T8: =_xlfn.XLOOKUP(TabelaClean14[[#This Row],[nome]],Base_Dirty!$B:$B,Base_Dirty!O:O) -> 39000 | U8: =IF(AND(TabelaClean14[[#This Row],[analise_risco]]="Arriscado",TabelaClean14[[#This Row],[analise_credito]]="Reprovado"),0,IF(TabelaClean14[[#This Row],[status]]="Ativo",TabelaClean14[[#This Row],[valor_solicitado]]*1.08,0)) -> 42120 | Y8: null | Z8: =PROPER(Y8) -> Null | AE8: 4900 | AF8: =TEXT(AE8,"000\.000\.000\-00") -> 000.000.049-00 | AJ8: 3800 | AK8: 3800 | AM8: 49500 | AN8: 49500 | AO8: 49500 | AQ8: Meereen | AZ8: 000.000.024-00 | BA8: Meereen | BB8: =_xlfn.XLOOKUP(TabelaClean14[[#This Row],[nome]],Base_Dirty!$B:$B,Base_Dirty!AX:AX) -> 0 | BC8: =IF(AND(TabelaClean14[[#This Row],[analise_risco]]="Arriscado",TabelaClean14[[#This Row],[analise_credito]]="Reprovado"),0,IF(TabelaClean14[[#This Row],[status]]="Ativo",TabelaClean14[[#This Row],[valor_solicitado]]*1.08,0)) -> 42120
A9: Ativo | B9: Meera Reed | C9: 000.000.280-00 | D9: =_xlfn.XLOOKUP(TabelaClean14[[#This Row],[nome]],Base_Dirty!B:B,Base_Dirty!E:E) -> 53 | E9: =_xlfn.XLOOKUP(TabelaClean14[[#This Row],[nome]],Base_Dirty!$B:$B,Base_Dirty!F:F) -> 26584 | F9: Fosso Cailin | G9: Norte | H9: Norte | I9: 12200 | J9: 79500 | K9: Nao | L9: 45 | M9: =_xlfn.XLOOKUP(TabelaClean14[[#This Row],[nome]],Base_Dirty!$B:$B,Base_Dirty!I:I) -> 12200 | N9: =_xlfn.XLOOKUP(TabelaClean14[[#This Row],[nome]],Base_Dirty!$B:$B,Base_Dirty!J:J) -> 79500 | O9: Nao | P9: =IF(AND(TabelaClean14[[#This Row],[credito_tomado]]>50000, TabelaClean14[[#This Row],[flag_inadimplente]]="Sim"), "Reprovado", IF(OR(ISBLANK(TabelaClean14[[#This Row],[credito_tomado]]), ISBLANK(TabelaClean14[[#This Row],[flag_inadimplente]])), "null", "Aprovado")) -> Aprovado | Q9: =_xlfn.XLOOKUP(TabelaClean14[[#This Row],[nome]],Base_Dirty!$B:$B,Base_Dirty!L:L) -> 45 | R9: {=_xlfn.IFS(TabelaClean14[[#This Row],[qtde_batalhas]]<=10,"Baixo",TabelaClean14[[#This Row],[qtde_batalhas]]>=26,"Alto",TabelaClean14[[#This Row],[qtde_batalhas]]<26,"Médio")} -> Alto | S9: =IF(AND(TabelaClean14[[#This Row],[nivel_risco]]="Alto",TabelaClean14[[#This Row],[flag_inadimplente]]="Sim"),"Arriscado","Ok") -> Ok | T9: =_xlfn.XLOOKUP(TabelaClean14[[#This Row],[nome]],Base_Dirty!$B:$B,Base_Dirty!O:O) -> 57000 | U9: =IF(AND(TabelaClean14[[#This Row],[analise_risco]]="Arriscado",TabelaClean14[[#This Row],[analise_credito]]="Reprovado"),0,IF(TabelaClean14[[#This Row],[status]]="Ativo",TabelaClean14[[#This Row],[valor_solicitado]]*1.08,0)) -> 61560 | Y9: ILHAS DE FERRO | Z9: =PROPER(Y9) -> Ilhas De Ferro | AE9: 6300 | AF9: =TEXT(AE9,"000\.000\.000\-00") -> 000.000.063-00 | AJ9: 14900 | AK9: 14900 | AM9: 17000 | AN9: 17000 | AO9: 17000 | AQ9: Harrenhal | AZ9: 000.000.143-00 | BA9: Harrenhal | BB9: =_xlfn.XLOOKUP(TabelaClean14[[#This Row],[nome]],Base_Dirty!$B:$B,Base_Dirty!AX:AX) -> 0 | BC9: =IF(AND(TabelaClean14[[#This Row],[analise_risco]]="Arriscado",TabelaClean14[[#This Row],[analise_credito]]="Reprovado"),0,IF(TabelaClean14[[#This Row],[status]]="Ativo",TabelaClean14[[#This Row],[valor_solicitado]]*1.08,0)) -> 61560
A10: Ativo | B10: Meera Reed | C10: =_xlfn.XLOOKUP(TabelaClean14[[#This Row],[nome]],Base_Dirty!$B:$B,Base_Dirty!D:D) -> 000.000.314-00 | D10: =_xlfn.XLOOKUP(TabelaClean14[[#This Row],[nome]],Base_Dirty!B:B,Base_Dirty!E:E) -> 53 | E10: 53 | F10: Fosso Cailin | G10: Norte | H10: Norte | I10: 12200 | J10: 79500 | K10: Nao | L10: 45 | M10: =_xlfn.XLOOKUP(TabelaClean14[[#This Row],[nome]],Base_Dirty!$B:$B,Base_Dirty!I:I) -> 12200 | N10: =_xlfn.XLOOKUP(TabelaClean14[[#This Row],[nome]],Base_Dirty!$B:$B,Base_Dirty!J:J) -> 79500 | O10: Não | P10: =IF(AND(TabelaClean14[[#This Row],[credito_tomado]]>50000, TabelaClean14[[#This Row],[flag_inadimplente]]="Sim"), "Reprovado", IF(OR(ISBLANK(TabelaClean14[[#This Row],[credito_tomado]]), ISBLANK(TabelaClean14[[#This Row],[flag_inadimplente]])), "null", "Aprovado")) -> Aprovado | Q10: =_xlfn.XLOOKUP(TabelaClean14[[#This Row],[nome]],Base_Dirty!$B:$B,Base_Dirty!L:L) -> 45 | R10: {=_xlfn.IFS(TabelaClean14[[#This Row],[qtde_batalhas]]<=10,"Baixo",TabelaClean14[[#This Row],[qtde_batalhas]]>=26,"Alto",TabelaClean14[[#This Row],[qtde_batalhas]]<26,"Médio")} -> Alto | S10: =IF(AND(TabelaClean14[[#This Row],[nivel_risco]]="Alto",TabelaClean14[[#This Row],[flag_inadimplente]]="Sim"),"Arriscado","Ok") -> Ok | T10: =_xlfn.XLOOKUP(TabelaClean14[[#This Row],[nome]],Base_Dirty!$B:$B,Base_Dirty!O:O) -> 57000 | U10: =IF(AND(TabelaClean14[[#This Row],[analise_risco]]="Arriscado",TabelaClean14[[#This Row],[analise_credito]]="Reprovado"),0,IF(TabelaClean14[[#This Row],[status]]="Ativo",TabelaClean14[[#This Row],[valor_solicitado]]*1.08,0)) -> 61560 | Y10: null | Z10: =PROPER(Y10) -> Null | AE10: 6400 | AF10: =TEXT(AE10,"000\.000\.000\-00") -> 000.000.064-00 | AJ10: 16800 | AK10: 16800 | AM10: 79500 | AN10: 79500 | AO10: 79500 | AQ10: Atalaia da Água Cinzenta | AZ10: 000.000.012-00 | BA10: Atalaia da Água Cinzenta | BB10: =_xlfn.XLOOKUP(TabelaClean14[[#This Row],[nome]],Base_Dirty!$B:$B,Base_Dirty!AX:AX) -> 0 | BC10: =IF(AND(TabelaClean14[[#This Row],[analise_risco]]="Arriscado",TabelaClean14[[#This Row],[analise_credito]]="Reprovado"),0,IF(TabelaClean14[[#This Row],[status]]="Ativo",TabelaClean14[[#This Row],[valor_solicitado]]*1.08,0)) -> 61560
A11: Inativo | B11: Eddard Dayne | C11: 000.000.032-00 | D11: 31 | E11: 34746 | F11: =TabelaClean14[[#This Row],[CidadeCPF]] -> Braavos | G11: =TabelaClean14[[#This Row],[RegiaoCPF]] -> Essos | H11: =_xlfn.XLOOKUP(TabelaClean14[[#This Row],[cpf]],TabelaDirty[cpfclean],TabelaDirty[cidade]) -> Braavos | I11: =_xlfn.XLOOKUP(TabelaClean14[[#This Row],[cpf]],TabelaDirty[cpfclean],TabelaDirty[regiao]) -> ESSOS | J11: =PROPER(TabelaClean14[[#This Row],[Coluna1]]) -> Essos | K11: =_xlfn.TEXTBEFORE(TabelaClean14[[#This Row],[CidadeCPF]]," | ") -> #N/A | L11: =_xlfn.TEXTAFTER(TabelaClean14[[#This Row],[CidadeCPF]]," | ") -> #N/A | M11: 18200 | N11: 78500 | O11: Não | P11: =IF(AND(TabelaClean14[[#This Row],[credito_tomado]]>50000, TabelaClean14[[#This Row],[flag_inadimplente]]="Sim"), "Reprovado", IF(OR(ISBLANK(TabelaClean14[[#This Row],[credito_tomado]]), ISBLANK(TabelaClean14[[#This Row],[flag_inadimplente]])), "null", "Aprovado")) -> Aprovado | Q11: 9 | R11: {=_xlfn.IFS(TabelaClean14[[#This Row],[qtde_batalhas]]<=10,"Baixo",TabelaClean14[[#This Row],[qtde_batalhas]]>=26,"Alto",TabelaClean14[[#This Row],[qtde_batalhas]]<26,"Médio")} -> Baixo | S11: =IF(AND(TabelaClean14[[#This Row],[nivel_risco]]="Alto",TabelaClean14[[#This Row],[flag_inadimplente]]="Sim"),"Arriscado","Ok") -> Ok | T11: 73000 | U11: =IF(AND(TabelaClean14[[#This Row],[analise_risco]]="Arriscado",TabelaClean14[[#This Row],[analise_credito]]="Reprovado"),0,IF(TabelaClean14[[#This Row],[status]]="Ativo",TabelaClean14[[#This Row],[valor_solicitado]]*1.08,0)) -> 0 | Y11: null | Z11: =PROPER(Y11) -> Null | AE11: 6900 | AF11: =TEXT(AE11,"000\.000\.000\-00") -> 000.000.069-00 | AJ11: 21600 | AK11: 21600 | AM11: 25000 | AN11: 25000 | AO11: 25000 | AQ11: Solar do Entardecer | AZ11: 000.000.028-00 | BA11: Solar do Entardecer | BB11: 18200 | BC11: =IF(AND(TabelaClean14[[#This Row],[analise_risco]]="Arriscado",TabelaClean14[[#This Row],[analise_credito]]="Reprovado"),0,IF(TabelaClean14[[#This Row],[status]]="Ativo",TabelaClean14[[#This Row],[valor_solicitado]]*1.08,0)) -> 0
A12: Ativo | B12: Jeor Florent | C12: 000.000.249-00 | D12: 27 | E12: 36319 | F12: =TabelaClean14[[#This Row],[CidadeCPF]] -> Ponta Tempestade | G12: =TabelaClean14[[#This Row],[RegiaoCPF]] -> Terras Da Tempestade | H12: =_xlfn.XLOOKUP(TabelaClean14[[#This Row],[cpf]],TabelaDirty[cpfclean],TabelaDirty[cidade]) -> Ponta Tempestade | I12: =_xlfn.XLOOKUP(TabelaClean14[[#This Row],[cpf]],TabelaDirty[cpfclean],TabelaDirty[regiao]) -> terras da tempestade | J12: =PROPER(TabelaClean14[[#This Row],[Coluna1]]) -> Terras Da Tempestade | K12: =_xlfn.TEXTBEFORE(TabelaClean14[[#This Row],[CidadeCPF]]," | ") -> #N/A | L12: =_xlfn.TEXTAFTER(TabelaClean14[[#This Row],[CidadeCPF]]," | ") -> #N/A | M12: 28800 | N12: 78500 | O12: Não | P12: =IF(AND(TabelaClean14[[#This Row],[credito_tomado]]>50000, TabelaClean14[[#This Row],[flag_inadimplente]]="Sim"), "Reprovado", IF(OR(ISBLANK(TabelaClean14[[#This Row],[credito_tomado]]), ISBLANK(TabelaClean14[[#This Row],[flag_inadimplente]])), "null", "Aprovado")) -> Aprovado | Q12: 2 | R12: {=_xlfn.IFS(TabelaClean14[[#This Row],[qtde_batalhas]]<=10,"Baixo",TabelaClean14[[#This Row],[qtde_batalhas]]>=26,"Alto",TabelaClean14[[#This Row],[qtde_batalhas]]<26,"Médio")} -> Baixo | S12: =IF(AND(TabelaClean14[[#This Row],[nivel_risco]]="Alto",TabelaClean14[[#This Row],[flag_inadimplente]]="Sim"),"Arriscado","Ok") -> Ok | T12: 53000 | U12: =IF(AND(TabelaClean14[[#This Row],[analise_risco]]="Arriscado",TabelaClean14[[#This Row],[analise_credito]]="Reprovado"),0,IF(TabelaClean14[[#This Row],[status]]="Ativo",TabelaClean14[[#This Row],[valor_solicitado]]*1.08,0)) -> 57240 | Y12: Terras Fluviais | Z12: =PROPER(Y12) -> Terras Fluviais | AE12: 7700 | AF12: =TEXT(AE12,"000\.000\.000\-00") -> 000.000.077-00 | AJ12: 3800 moedas | AK12: 3800 | AM12: 0 | AN12: 0 | AO12: 0 | AQ12: Braavos | AZ12: 000.000.169-00 | BA12: Braavos | BB12: 28800 | BC12: =IF(AND(TabelaClean14[[#This Row],[analise_risco]]="Arriscado",TabelaClean14[[#This Row],[analise_credito]]="Reprovado"),0,IF(TabelaClean14[[#This Row],[status]]="Ativo",TabelaClean14[[#This Row],[valor_solicitado]]*1.08,0)) -> 57240
A13: Ativo | B13: Petyr Swyft | C13: 000.000.275-00 | D13: 36 | E13: 33117 | F13: =TabelaClean14[[#This Row],[CidadeCPF]] -> Atalaia da Água Cinzenta | G13: =TabelaClean14[[#This Row],[RegiaoCPF]] -> Gargalo | H13: =_xlfn.XLOOKUP(TabelaClean14[[#This Row],[cpf]],TabelaDirty[cpfclean],TabelaDirty[cidade]) -> Atalaia da Água Cinzenta | I13: =_xlfn.XLOOKUP(TabelaClean14[[#This Row],[cpf]],TabelaDirty[cpfclean],TabelaDirty[regiao]) -> Gargalo | J13: =PROPER(TabelaClean14[[#This Row],[Coluna1]]) -> Gargalo | K13: =_xlfn.TEXTBEFORE(TabelaClean14[[#This Row],[CidadeCPF]]," | ") -> #N/A | L13: =_xlfn.TEXTAFTER(TabelaClean14[[#This Row],[CidadeCPF]]," | ") -> #N/A | M13: 11600 | N13: 78500 | O13: Não | P13: =IF(AND(TabelaClean14[[#This Row],[credito_tomado]]>50000, TabelaClean14[[#This Row],[flag_inadimplente]]="Sim"), "Reprovado", IF(OR(ISBLANK(TabelaClean14[[#This Row],[credito_tomado]]), ISBLANK(TabelaClean14[[#This Row],[flag_inadimplente]])), "null", "Aprovado")) -> Aprovado | Q13: 1 | R13: {=_xlfn.IFS(TabelaClean14[[#This Row],[qtde_batalhas]]<=10,"Baixo",TabelaClean14[[#This Row],[qtde_batalhas]]>=26,"Alto",TabelaClean14[[#This Row],[qtde_batalhas]]<26,"Médio")} -> Baixo | S13: =IF(AND(TabelaClean14[[#This Row],[nivel_risco]]="Alto",TabelaClean14[[#This Row],[flag_inadimplente]]="Sim"),"Arriscado","Ok") -> Ok | T13: 42000 | U13: =IF(AND(TabelaClean14[[#This Row],[analise_risco]]="Arriscado",TabelaClean14[[#This Row],[analise_credito]]="Reprovado"),0,IF(TabelaClean14[[#This Row],[status]]="Ativo",TabelaClean14[[#This Row],[valor_solicitado]]*1.08,0)) -> 45360 | Y13: null | Z13: =PROPER(Y13) -> Null | AE13: 8200 | AF13: =TEXT(AE13,"000\.000\.000\-00") -> 000.000.082-00 | AJ13: 25200 | AK13: 25200 | AM13: 59500 | AN13: 59500 | AO13: 59500 | AQ13: Jardim de Cima | AZ13: 000.000.257-00 | BA13: Jardim de Cima | BB13: 11600 | BC13: =IF(AND(TabelaClean14[[#This Row],[analise_risco]]="Arriscado",TabelaClean14[[#This Row],[analise_credito]]="Reprovado"),0,IF(TabelaClean14[[#This Row],[status]]="Ativo",TabelaClean14[[#This Row],[valor_solicitado]]*1.08,0)) -> 45360
A14: Inativo | B14: Thoros Hornwood | C14: 000.000.245-00 | D14: 65 | E14: 22205 | F14: =TabelaClean14[[#This Row],[CidadeCPF]] -> Castelo Negro | G14: =TabelaClean14[[#This Row],[RegiaoCPF]] -> Norte | H14: =_xlfn.XLOOKUP(TabelaClean14[[#This Row],[cpf]],TabelaDirty[cpfclean],TabelaDirty[cidade]) -> Castelo Negro | I14: =_xlfn.XLOOKUP(TabelaClean14[[#This Row],[cpf]],TabelaDirty[cpfclean],TabelaDirty[regiao]) -> Norte | J14: =PROPER(TabelaClean14[[#This Row],[Coluna1]]) -> Norte | K14: =_xlfn.TEXTBEFORE(TabelaClean14[[#This Row],[CidadeCPF]]," | ") -> #N/A | L14: =_xlfn.TEXTAFTER(TabelaClean14[[#This Row],[CidadeCPF]]," | ") -> #N/A | M14: 19800 | N14: 78500 | O14: Não | P14: =IF(AND(TabelaClean14[[#This Row],[credito_tomado]]>50000, TabelaClean14[[#This Row],[flag_inadimplente]]="Sim"), "Reprovado", IF(OR(ISBLANK(TabelaClean14[[#This Row],[credito_tomado]]), ISBLANK(TabelaClean14[[#This Row],[flag_inadimplente]])), "null", "Aprovado")) -> Aprovado | Q14: 34 | R14: {=_xlfn.IFS(TabelaClean14[[#This Row],[qtde_batalhas]]<=10,"Baixo",TabelaClean14[[#This Row],[qtde_batalhas]]>=26,"Alto",TabelaClean14[[#This Row],[qtde_batalhas]]<26,"Médio")} -> Alto | S14: =IF(AND(TabelaClean14[[#This Row],[nivel_risco]]="Alto",TabelaClean14[[#This Row],[flag_inadimplente]]="Sim"),"Arriscado","Ok") -> Ok | T14: 23000 | U14: =IF(AND(TabelaClean14[[#This Row],[analise_risco]]="Arriscado",TabelaClean14[[#This Row],[analise_credito]]="Reprovado"),0,IF(TabelaClean14[[#This Row],[status]]="Ativo",TabelaClean14[[#This Row],[valor_solicitado]]*1.08,0)) -> 0 | Y14: Essos | Z14: =PROPER(Y14) -> Essos | AE14: 8600 | AF14: =TEXT(AE14,"000\.000\.000\-00") -> 000.000.086-00 | AJ14: 16300 | AK14: 16300 | AM14: 16500 | AN14: 16500 | AO14: 16500 | AQ14: Vilavelha | AZ14: 000.000.108-00 | BA14: Vilavelha | BB14: 19800 | BC14: =IF(AND(TabelaClean14[[#This Row],[analise_risco]]="Arriscado",TabelaClean14[[#This Row],[analise_credito]]="Reprovado"),0,IF(TabelaClean14[[#This Row],[status]]="Ativo",TabelaClean14[[#This Row],[valor_solicitado]]*1.08,0)) -> 0
A15: Inativo | B15: Thoros Hornwood | C15: 000.000.245-00 | D15: 65 | E15: 22205 | F15: Castelo Negro | G15: Norte | H15: 19800 | I15: 78500 | J15: Não | K15: 34 | M15: 84000 | N15: 78500 | O15: Não | P15: =IF(AND(TabelaClean14[[#This Row],[credito_tomado]]>50000, TabelaClean14[[#This Row],[flag_inadimplente]]="Sim"), "Reprovado", IF(OR(ISBLANK(TabelaClean14[[#This Row],[credito_tomado]]), ISBLANK(TabelaClean14[[#This Row],[flag_inadimplente]])), "null", "Aprovado")) -> Aprovado | Q15: 34 | R15: {=_xlfn.IFS(TabelaClean14[[#This Row],[qtde_batalhas]]<=10,"Baixo",TabelaClean14[[#This Row],[qtde_batalhas]]>=26,"Alto",TabelaClean14[[#This Row],[qtde_batalhas]]<26,"Médio")} -> Alto | S15: =IF(AND(TabelaClean14[[#This Row],[nivel_risco]]="Alto",TabelaClean14[[#This Row],[flag_inadimplente]]="Sim"),"Arriscado","Ok") -> Ok | T15: 84000 | U15: =IF(AND(TabelaClean14[[#This Row],[analise_risco]]="Arriscado",TabelaClean14[[#This Row],[analise_credito]]="Reprovado"),0,IF(TabelaClean14[[#This Row],[status]]="Ativo",TabelaClean14[[#This Row],[valor_solicitado]]*1.08,0)) -> 0 | Y15: null | Z15: =PROPER(Y15) -> Null | AE15: 9600 | AF15: =TEXT(AE15,"000\.000\.000\-00") -> 000.000.096-00 | AJ15: 16100 | AK15: 16100 | AM15: 8000 | AN15: 8000 | AO15: 8000 | AQ15: Fosso Cailin | AZ15: 000.000.091-00 | BA15: Fosso Cailin | BB15: 84000 | BC15: =IF(AND(TabelaClean14[[#This Row],[analise_risco]]="Arriscado",TabelaClean14[[#This Row],[analise_credito]]="Reprovado"),0,IF(TabelaClean14[[#This Row],[status]]="Ativo",TabelaClean14[[#This Row],[valor_solicitado]]*1.08,0)) -> 0
A16: Ativo | B16: Aegon Baelish | C16: 000.000.240-00 | D16: 47 | E16: 29031 | F16: =TabelaClean14[[#This Row],[CidadeClean]] -> Meereen | G16: =TabelaClean14[[#This Row],[RegiaoClean]] -> Essos | H16: =_xlfn.XLOOKUP(TabelaClean14[[#This Row],[cpf]],TabelaDirty[cpfclean],TabelaDirty[cidade]) -> Meereen | Essos | I16: =_xlfn.XLOOKUP(TabelaClean14[[#This Row],[cpf]],TabelaDirty[cpfclean],TabelaDirty[regiao]) -> 0 | J16: Essos | K16: =_xlfn.TEXTBEFORE(TabelaClean14[[#This Row],[CidadeCPF]]," | ") -> Meereen | L16: =_xlfn.TEXTAFTER(TabelaClean14[[#This Row],[CidadeCPF]]," | ") -> Essos | M16: 28400 | N16: 78000 | O16: Não | P16: =IF(AND(TabelaClean14[[#This Row],[credito_tomado]]>50000, TabelaClean14[[#This Row],[flag_inadimplente]]="Sim"), "Reprovado", IF(OR(ISBLANK(TabelaClean14[[#This Row],[credito_tomado]]), ISBLANK(TabelaClean14[[#This Row],[flag_inadimplente]])), "null", "Aprovado")) -> Aprovado | Q16: 37 | R16: {=_xlfn.IFS(TabelaClean14[[#This Row],[qtde_batalhas]]<=10,"Baixo",TabelaClean14[[#This Row],[qtde_batalhas]]>=26,"Alto",TabelaClean14[[#This Row],[qtde_batalhas]]<26,"Médio")} -> Alto | S16: =IF(AND(TabelaClean14[[#This Row],[nivel_risco]]="Alto",TabelaClean14[[#This Row],[flag_inadimplente]]="Sim"),"Arriscado","Ok") -> Ok | T16: 99000 | U16: =IF(AND(TabelaClean14[[#This Row],[analise_risco]]="Arriscado",TabelaClean14[[#This Row],[analise_credito]]="Reprovado"),0,IF(TabelaClean14[[#This Row],[status]]="Ativo",TabelaClean14[[#This Row],[valor_solicitado]]*1.08,0)) -> 106920 | Y16: null | Z16: =PROPER(Y16) -> Null | AE16: 9800 | AF16: =TEXT(AE16,"000\.000\.000\-00") -> 000.000.098-00 | AJ16: 19400 | AK16: 19400 | AM16: 4000 | AN16: 4000 | AO16: 4000 | AQ16: Castelo Negro | AZ16: 000.000.270-00 | BA16: Castelo Negro | BB16: 28400 | BC16: =IF(AND(TabelaClean14[[#This Row],[analise_risco]]="Arriscado",TabelaClean14[[#This Row],[analise_credito]]="Reprovado"),0,IF(TabelaClean14[[#This Row],[status]]="Ativo",TabelaClean14[[#This Row],[valor_solicitado]]*1.08,0)) -> 106920
A17: Inativo | B17: Gilly Frey | C17: 000.000.258-00 | D17: 33 | E17: 34154 | F17: =TabelaClean14[[#This Row],[CidadeCPF]] -> Castelo Negro | G17: =TabelaClean14[[#This Row],[RegiaoCPF]] -> Norte | H17: =_xlfn.XLOOKUP(TabelaClean14[[#This Row],[cpf]],TabelaDirty[cpfclean],TabelaDirty[cidade]) -> Castelo Negro | I17: =_xlfn.XLOOKUP(TabelaClean14[[#This Row],[cpf]],TabelaDirty[cpfclean],TabelaDirty[regiao]) -> Norte | J17: =PROPER(TabelaClean14[[#This Row],[Coluna1]]) -> Norte | K17: =_xlfn.TEXTBEFORE(TabelaClean14[[#This Row],[CidadeCPF]]," | ") -> #N/A | L17: =_xlfn.TEXTAFTER(TabelaClean14[[#This Row],[CidadeCPF]]," | ") -> #N/A | M17: 2400 | N17: 78000 | O17: Não | P17: =IF(AND(TabelaClean14[[#This Row],[credito_tomado]]>50000, TabelaClean14[[#This Row],[flag_inadimplente]]="Sim"), "Reprovado", IF(OR(ISBLANK(TabelaClean14[[#This Row],[credito_tomado]]), ISBLANK(TabelaClean14[[#This Row],[flag_inadimplente]])), "null", "Aprovado")) -> Aprovado | Q17: 6 | R17: {=_xlfn.IFS(TabelaClean14[[#This Row],[qtde_batalhas]]<=10,"Baixo",TabelaClean14[[#This Row],[qtde_batalhas]]>=26,"Alto",TabelaClean14[[#This Row],[qtde_batalhas]]<26,"Médio")} -> Baixo | S17: =IF(AND(TabelaClean14[[#This Row],[nivel_risco]]="Alto",TabelaClean14[[#This Row],[flag_inadimplente]]="Sim"),"Arriscado","Ok") -> Ok | T17: 28000 | U17: =IF(AND(TabelaClean14[[#This Row],[analise_risco]]="Arriscado",TabelaClean14[[#This Row],[analise_credito]]="Reprovado"),0,IF(TabelaClean14[[#This Row],[status]]="Ativo",TabelaClean14[[#This Row],[valor_solicitado]]*1.08,0)) -> 0 | Y17: null | Z17: =PROPER(Y17) -> Null | AE17: 9900 | AF17: =TEXT(AE17,"000\.000\.000\-00") -> 000.000.099-00 | AJ17: 21500 moedas | AK17: 21500 | AM17: N/A | AN17: null | AO17: null | AQ17: Solar do Entardecer | AZ17: 000.000.344-00 | BA17: Solar do Entardecer | BB17: 2400 | BC17: =IF(AND(TabelaClean14[[#This Row],[analise_risco]]="Arriscado",TabelaClean14[[#This Row],[analise_credito]]="Reprovado"),0,IF(TabelaClean14[[#This Row],[status]]="Ativo",TabelaClean14[[#This Row],[valor_solicitado]]*1.08,0)) -> 0
A18: Inativo | B18: Renly Redwyne | C18: 000.000.045-00 | D18: 66 | E18: 21954 | F18: =TabelaClean14[[#This Row],[CidadeCPF]] -> Porto Real | G18: =TabelaClean14[[#This Row],[RegiaoCPF]] -> Terras Da Coroa | H18: =_xlfn.XLOOKUP(TabelaClean14[[#This Row],[cpf]],TabelaDirty[cpfclean],TabelaDirty[cidade]) -> Porto Real | I18: =_xlfn.XLOOKUP(TabelaClean14[[#This Row],[cpf]],TabelaDirty[cpfclean],TabelaDirty[regiao]) -> TERRAS DA COROA | J18: =PROPER(TabelaClean14[[#This Row],[Coluna1]]) -> Terras Da Coroa | K18: =_xlfn.TEXTBEFORE(TabelaClean14[[#This Row],[CidadeCPF]]," | ") -> #N/A | L18: =_xlfn.TEXTAFTER(TabelaClean14[[#This Row],[CidadeCPF]]," | ") -> #N/A | M18: 3400 | N18: 78000 | O18: Não | P18: =IF(AND(TabelaClean14[[#This Row],[credito_tomado]]>50000, TabelaClean14[[#This Row],[flag_inadimplente]]="Sim"), "Reprovado", IF(OR(ISBLANK(TabelaClean14[[#This Row],[credito_tomado]]), ISBLANK(TabelaClean14[[#This Row],[flag_inadimplente]])), "null", "Aprovado")) -> Aprovado | Q18: 9 | R18: {=_xlfn.IFS(TabelaClean14[[#This Row],[qtde_batalhas]]<=10,"Baixo",TabelaClean14[[#This Row],[qtde_batalhas]]>=26,"Alto",TabelaClean14[[#This Row],[qtde_batalhas]]<26,"Médio")} -> Baixo | S18: =IF(AND(TabelaClean14[[#This Row],[nivel_risco]]="Alto",TabelaClean14[[#This Row],[flag_inadimplente]]="Sim"),"Arriscado","Ok") -> Ok | T18: 51500 | U18: =IF(AND(TabelaClean14[[#This Row],[analise_risco]]="Arriscado",TabelaClean14[[#This Row],[analise_credito]]="Reprovado"),0,IF(TabelaClean14[[#This Row],[status]]="Ativo",TabelaClean14[[#This Row],[valor_solicitado]]*1.08,0)) -> 0 | Y18: null | Z18: =PROPER(Y18) -> Null | AE18: 10200 | AF18: =TEXT(AE18,"000\.000\.000\-00") -> 000.000.102-00 | AJ18: 13800 | AK18: 13800 | AM18: 41500 | AN18: 41500 | AO18: 41500 | AQ18: Monte Chifre | AZ18: 000.000.080-00 | BA18: Monte Chifre | BB18: 3400 | BC18: =IF(AND(TabelaClean14[[#This Row],[analise_risco]]="Arriscado",TabelaClean14[[#This Row],[analise_credito]]="Reprovado"),0,IF(TabelaClean14[[#This Row],[status]]="Ativo",TabelaClean14[[#This Row],[valor_solicitado]]*1.08,0)) -> 0
A19: inativo | B19: Varys Tallhart | C19: =_xlfn.XLOOKUP(TabelaClean14[[#This Row],[nome]],Base_Dirty!$B:$B,Base_Dirty!D:D) -> 000.000.000-00 | D19: =_xlfn.XLOOKUP(TabelaClean14[[#This Row],[nome]],Base_Dirty!B:B,Base_Dirty!E:E) -> 61 | E19: =_xlfn.XLOOKUP(TabelaClean14[[#This Row],[nome]],Base_Dirty!$B:$B,Base_Dirty!F:F) -> 23932 | F19: Correrrio | G19: Terras Fluviais | H19: Terras Fluviais | I19: 4100 | J19: 78000 | K19: Não | L19: 25 | M19: =_xlfn.XLOOKUP(TabelaClean14[[#This Row],[nome]],Base_Dirty!$B:$B,Base_Dirty!I:I) -> 4100 | N19: =_xlfn.XLOOKUP(TabelaClean14[[#This Row],[nome]],Base_Dirty!$B:$B,Base_Dirty!J:J) -> 78000 | O19: Não | P19: =IF(AND(TabelaClean14[[#This Row],[credito_tomado]]>50000, TabelaClean14[[#This Row],[flag_inadimplente]]="Sim"), "Reprovado", IF(OR(ISBLANK(TabelaClean14[[#This Row],[credito_tomado]]), ISBLANK(TabelaClean14[[#This Row],[flag_inadimplente]])), "null", "Aprovado")) -> Aprovado | Q19: =_xlfn.XLOOKUP(TabelaClean14[[#This Row],[nome]],Base_Dirty!$B:$B,Base_Dirty!L:L) -> 25 | R19: {=_xlfn.IFS(TabelaClean14[[#This Row],[qtde_batalhas]]<=10,"Baixo",TabelaClean14[[#This Row],[qtde_batalhas]]>=26,"Alto",TabelaClean14[[#This Row],[qtde_batalhas]]<26,"Médio")} -> Médio | S19: =IF(AND(TabelaClean14[[#This Row],[nivel_risco]]="Alto",TabelaClean14[[#This Row],[flag_inadimplente]]="Sim"),"Arriscado","Ok") -> Ok | T19: =_xlfn.XLOOKUP(TabelaClean14[[#This Row],[nome]],Base_Dirty!$B:$B,Base_Dirty!O:O) -> 48000 | U19: =IF(AND(TabelaClean14[[#This Row],[analise_risco]]="Arriscado",TabelaClean14[[#This Row],[analise_credito]]="Reprovado"),0,IF(TabelaClean14[[#This Row],[status]]="Ativo",TabelaClean14[[#This Row],[valor_solicitado]]*1.08,0)) -> 0 | Y19: null | Z19: =PROPER(Y19) -> Null | AE19: 10800 | AF19: =TEXT(AE19,"000\.000\.000\-00") -> 000.000.108-00 | AJ19: 8400 | AK19: 8400 | AM19: 62500 | AN19: 62500 | AO19: 62500 | AQ19: Fosso Cailin | AZ19: 000.000.051-00 | BA19: Fosso Cailin | BB19: =_xlfn.XLOOKUP(TabelaClean14[[#This Row],[nome]],Base_Dirty!$B:$B,Base_Dirty!AX:AX) -> 0 | BC19: =IF(AND(TabelaClean14[[#This Row],[analise_risco]]="Arriscado",TabelaClean14[[#This Row],[analise_credito]]="Reprovado"),0,IF(TabelaClean14[[#This Row],[status]]="Ativo",TabelaClean14[[#This Row],[valor_solicitado]]*1.08,0)) -> 0
A20: Inativo | B20: Eddard Stark | C20: 000.000.015-00 | D20: 55 | E20: 26142 | F20: =TabelaClean14[[#This Row],[CidadeCPF]] -> Ninho da Águia | G20: =TabelaClean14[[#This Row],[RegiaoCPF]] -> Vale | H20: =_xlfn.XLOOKUP(TabelaClean14[[#This Row],[cpf]],TabelaDirty[cpfclean],TabelaDirty[cidade]) -> Ninho da Águia | I20: =_xlfn.XLOOKUP(TabelaClean14[[#This Row],[cpf]],TabelaDirty[cpfclean],TabelaDirty[regiao]) -> VALE | J20: =PROPER(TabelaClean14[[#This Row],[Coluna1]]) -> Vale | K20: =_xlfn.TEXTBEFORE(TabelaClean14[[#This Row],[CidadeCPF]]," | ") -> #N/A | L20: =_xlfn.TEXTAFTER(TabelaClean14[[#This Row],[CidadeCPF]]," | ") -> #N/A | M20: 29700 | N20: 78000 | O20: Sim | P20: =IF(AND(TabelaClean14[[#This Row],[credito_tomado]]>50000, TabelaClean14[[#This Row],[flag_inadimplente]]="Sim"), "Reprovado", IF(OR(ISBLANK(TabelaClean14[[#This Row],[credito_tomado]]), ISBLANK(TabelaClean14[[#This Row],[flag_inadimplente]])), "null", "Aprovado")) -> Reprovado | Q20: 14 | R20: {=_xlfn.IFS(TabelaClean14[[#This Row],[qtde_batalhas]]<=10,"Baixo",TabelaClean14[[#This Row],[qtde_batalhas]]>=26,"Alto",TabelaClean14[[#This Row],[qtde_batalhas]]<26,"Médio")} -> Médio | S20: =IF(AND(TabelaClean14[[#This Row],[nivel_risco]]="Alto",TabelaClean14[[#This Row],[flag_inadimplente]]="Sim"),"Arriscado","Ok") -> Ok | T20: 27000 | U20: =IF(AND(TabelaClean14[[#This Row],[analise_risco]]="Arriscado",TabelaClean14[[#This Row],[analise_credito]]="Reprovado"),0,IF(TabelaClean14[[#This Row],[status]]="Ativo",TabelaClean14[[#This Row],[valor_solicitado]]*1.08,0)) -> 0 | Y20: Ilhas de Ferro | Z20: =PROPER(Y20) -> Ilhas De Ferro | AE20: 11600 | AF20: =TEXT(AE20,"000\.000\.000\-00") -> 000.000.116-00 | AJ20: 17600 moedas | AK20: 17600 | AM20: 0 | AN20: 0 | AO20: 0 | AQ20: Monte Chifre | AZ20: 000.000.253-00 | BA20: Monte Chifre | BB20: 29700 | BC20: =IF(AND(TabelaClean14[[#This Row],[analise_risco]]="Arriscado",TabelaClean14[[#This Row],[analise_credito]]="Reprovado"),0,IF(TabelaClean14[[#This Row],[status]]="Ativo",TabelaClean14[[#This Row],[valor_solicitado]]*1.08,0)) -> 0
A21: Inativo | B21: Jeor Baelish | C21: 000.000.332-00 | D21: 66 | E21: 22039 | F21: =TabelaClean14[[#This Row],[CidadeCPF]] -> Dorne | G21: =TabelaClean14[[#This Row],[RegiaoCPF]] -> Dorne | H21: =_xlfn.XLOOKUP(TabelaClean14[[#This Row],[cpf]],TabelaDirty[cpfclean],TabelaDirty[cidade]) -> Dorne | I21: =_xlfn.XLOOKUP(TabelaClean14[[#This Row],[cpf]],TabelaDirty[cpfclean],TabelaDirty[regiao]) -> dorne | J21: =PROPER(TabelaClean14[[#This Row],[Coluna1]]) -> Dorne | K21: =_xlfn.TEXTBEFORE(TabelaClean14[[#This Row],[CidadeCPF]]," | ") -> #N/A | L21: =_xlfn.TEXTAFTER(TabelaClean14[[#This Row],[CidadeCPF]]," | ") -> #N/A | M21: 14300 | N21: 78000 | O21: Não | P21: =IF(AND(TabelaClean14[[#This Row],[credito_tomado]]>50000, TabelaClean14[[#This Row],[flag_inadimplente]]="Sim"), "Reprovado", IF(OR(ISBLANK(TabelaClean14[[#This Row],[credito_tomado]]), ISBLANK(TabelaClean14[[#This Row],[flag_inadimplente]])), "null", "Aprovado")) -> Aprovado | Q21: 28 | R21: {=_xlfn.IFS(TabelaClean14[[#This Row],[qtde_batalhas]]<=10,"Baixo",TabelaClean14[[#This Row],[qtde_batalhas]]>=26,"Alto",TabelaClean14[[#This Row],[qtde_batalhas]]<26,"Médio")} -> Alto | S21: =IF(AND(TabelaClean14[[#This Row],[nivel_risco]]="Alto",TabelaClean14[[#This Row],[flag_inadimplente]]="Sim"),"Arriscado","Ok") -> Ok | T21: 74500 | U21: =IF(AND(TabelaClean14[[#This Row],[analise_risco]]="Arriscado",TabelaClean14[[#This Row],[analise_credito]]="Reprovado"),0,IF(TabelaClean14[[#This Row],[status]]="Ativo",TabelaClean14[[#This Row],[valor_solicitado]]*1.08,0)) -> 0 | Y21: null | Z21: =PROPER(Y21) -> Null | AE21: 11700 | AF21: =TEXT(AE21,"000\.000\.000\-00") -> 000.000.117-00 | AJ21: 28900 | AK21: 28900 | AM21: 71000 | AN21: 71000 | AO21: 71000 | AQ21: Braavos | AZ21: 000.000.027-00 | BA21: Braavos | BB21: 14300 | BC21: =IF(AND(TabelaClean14[[#This Row],[analise_risco]]="Arriscado",TabelaClean14[[#This Row],[analise_credito]]="Reprovado"),0,IF(TabelaClean14[[#This Row],[status]]="Ativo",TabelaClean14[[#This Row],[valor_solicitado]]*1.08,0)) -> 0
A22: Inativo | B22: Stannis Lannister | C22: 000.000.361-00 | D22: 24 | E22: 37313 | F22: =TabelaClean14[[#This Row],[CidadeCPF]] -> Ponta Tempestade | G22: =TabelaClean14[[#This Row],[RegiaoCPF]] -> Terras Da Tempestade | H22: =_xlfn.XLOOKUP(TabelaClean14[[#This Row],[cpf]],TabelaDirty[cpfclean],TabelaDirty[cidade]) -> Ponta Tempestade | I22: =_xlfn.XLOOKUP(TabelaClean14[[#This Row],[cpf]],TabelaDirty[cpfclean],TabelaDirty[regiao]) -> Terras da Tempestade | J22: =PROPER(TabelaClean14[[#This Row],[Coluna1]]) -> Terras Da Tempestade | K22: =_xlfn.TEXTBEFORE(TabelaClean14[[#This Row],[CidadeCPF]]," | ") -> #N/A | L22: =_xlfn.TEXTAFTER(TabelaClean14[[#This Row],[CidadeCPF]]," | ") -> #N/A | M22: 11000 | N22: 76500 | O22: Sim | P22: =IF(AND(TabelaClean14[[#This Row],[credito_tomado]]>50000, TabelaClean14[[#This Row],[flag_inadimplente]]="Sim"), "Reprovado", IF(OR(ISBLANK(TabelaClean14[[#This Row],[credito_tomado]]), ISBLANK(TabelaClean14[[#This Row],[flag_inadimplente]])), "null", "Aprovado")) -> Reprovado | Q22: 33 | R22: {=_xlfn.IFS(TabelaClean14[[#This Row],[qtde_batalhas]]<=10,"Baixo",TabelaClean14[[#This Row],[qtde_batalhas]]>=26,"Alto",TabelaClean14[[#This Row],[qtde_batalhas]]<26,"Médio")} -> Alto | S22: =IF(AND(TabelaClean14[[#This Row],[nivel_risco]]="Alto",TabelaClean14[[#This Row],[flag_inadimplente]]="Sim"),"Arriscado","Ok") -> Arriscado | T22: 26000 | U22: =IF(AND(TabelaClean14[[#This Row],[analise_risco]]="Arriscado",TabelaClean14[[#This Row],[analise_credito]]="Reprovado"),0,IF(TabelaClean14[[#This Row],[status]]="Ativo",TabelaClean14[[#This Row],[valor_solicitado]]*1.08,0)) -> 0 | Y22: terras da coroa | Z22: =PROPER(Y22) -> Terras Da Coroa | AE22: 12700 | AF22: =TEXT(AE22,"000\.000\.000\-00") -> 000.000.127-00 | AJ22: 12700 | AK22: 12700 | AM22: 79500 | AN22: 79500 | AO22: 79500 | AQ22: Ponta Tempestade | AZ22: 000.000.297-00 | BA22: Ponta Tempestade | BB22: 11000 | BC22: =IF(AND(TabelaClean14[[#This Row],[analise_risco]]="Arriscado",TabelaClean14[[#This Row],[analise_credito]]="Reprovado"),0,IF(TabelaClean14[[#This Row],[status]]="Ativo",TabelaClean14[[#This Row],[valor_solicitado]]*1.08,0)) -> 0
